Workbook

Sheet Cover
B2: NETFLIX, INC.
B3: NASDAQ: NFLX | Independent Equity-Research-Style Financial Model
B5: Three-Statement Operating Model • Scenario Analysis (Worst / Neutral / Best) • DCF Valuation
B8: A bottom-up, three-statement model built from Netflix's FY2023-FY2025 actuals, with a live scenario engine (Worst / Neutral / Best) driving revenue, margins, working capital, and a DCF valuation. Built as a portfolio project to demonstrate FP&A-style financial modeling: linked statements, sourced assumptions, and a documented audit trail -- not just a static forecast.
B9: Data source: FY2025 Form 10-K (SEC accession 0001065280-26-000034, filed 2026-01-23), covering FY2023-FY2025 actuals. Prepared July 2026.
B16: How to use this model
B17: 1. Set the scenario on the 'Model Control' tab (cell B3: pick Worst / Neutral / Best from the dropdown). This is the single master switch -- every tab updates from it.
B18: 2. 'Assumptions' holds every driver with its rationale, sourced to the 10-K MD&A where Netflix discloses one, and flagged where a figure is an analyst estimate. One tab, one format.
B19: 3. 'Proj Drivers' resolves the selected scenario into single driver values; 'Proj Schedules' builds the supporting rollforwards (revenue by region, content assets, PP&E, debt, working capital, equity).
B20: 4. 'Projected PnL / BS / CFS' are the fully linked three-statement output. 'Checks' confirms the balance sheet balances and cash ties out under every scenario.
B21: 5. 'WACC' and 'DCF' derive an intrinsic value per share and compare it to the market price.
B23: A note on methodology: why this model is revenue-driven, not subscriber-driven
... B51: 'Chart Data' computes Worst/Neutral/Best in parallel (independent of the Model Control switch) so all three scenarios can be charted at once. 'Charts' holds 7 native, editable Excel charts: Revenue, Cost of Revenue, Operating Expenses, Operating Income, Net Profit, and Operating Margin % (each with 3 scenario lines), plus a regional revenue mix chart for the Neutral case.

Sheet Model Control
A1: Model Control — Scenario Selector & Projection Assumptions
A2: NOTE: This is the single master scenario switch for the whole model (drives Assumptions, Proj Drivers, Chart Data, and every projected statement).
A3: Select Scenario (dropdown) -> | B3: Neutral | C3: =MATCH($B$3,{"Worst","Neutral","Best"},0) -> 2 | D3: (numeric index -- every CHOOSE() formula in the model reads this cell; do not edit directly, use the dropdown in B3)
A4: Active scenario | C4: =CHOOSE($C$3,"Worst Case","Neutral Case","Best Case") -> Neutral Case
A6: Single-point operating drivers (not scenario-varied; not year-by-year) -- see Assumptions tab for all scenario-driven % drivers
A10: Capex as % of revenue | C10: 0.015
A11: Depreciation as % of opening PP&E | C11: ='CFS Input'!D9/'Balance Sheet Input'!C11 -> 0.20918447 | D11: <- corrected: was hardcoded at 7.0%, a 3x understatement vs the actual 2025A ratio; now a live formula.
A12: Content amortization as % of opening content | C12: 0.5
A13: Current content liabilities as % of revenue | C13: 0.09
A14: Non-current content liabilities as % of revenue | C14: 0.035
A15: Other non-current assets as % of revenue | C15: 0.1725
A16: Other non-current liabilities as % of revenue | C16: 0.0655
A17: Stock-based compensation as % of revenue | C17: 0.0082
A18: Stock issuance proceeds as % of revenue | C18: 0.0148
A19: Debt weighted-average interest rate | C19: =Debt!D55 -> 0.0476 | D19: <- corrected: was a hardcoded flat 5.0% guess; now linked to the Debt tab's actual note-by-note weighted-average rate (4.76%).
A20: Short-term investments (held flat) | C20: 28678
A22: Share repurchases (capital-return policy) by year — KEY INPUT | C22: 2026E | D22: 2027E | E22: 2028E | F22: 2029E | G22: 2030E
A23: Buybacks | C23: 9127167 | D23: 9127167 | E23: 9127167 | F23: 9127167 | G23: 9127167

Sheet Assumptions
A1: Netflix, Inc. — Assumptions (single source of truth for all scenario drivers)
A2: Percent drivers stored as fractions; $ drivers in USD thousands. Source: FY2025 Form 10-K MD&A unless flagged as analyst estimate. The model reads only the "Selected" row of each block, which follows Model Control!B3.
A4: UCAN Revenue Growth %
A5: UCAN grew 15.0%-16.7% in 2024-2025, but that was inflated by two one-time catalysts: the 2023 paid-sharing crackdown converting freeloaders to payers, and the ad-tier ramping from launch. UCAN is Netflix's most penetrated market, so Neutral (5%) assumes that tailwind fades and growth reverts to a price-led, low-single-to-mid-single-digit pace. Worst (3%) reflects price-increase pushback/churn or a weaker ad-tier ramp; Best (7%) assumes stronger pricing power and live-sports/events engagement than the base case.
A6: Scenario | C6: 2025A | D6: 2026E | E6: 2027E | F6: 2028E | G6: 2029E | H6: 2030E
A7: Worst | C7: 0.03 | D7: 0.03 | E7: 0.03 | F7: 0.03 | G7: 0.03 | H7: 0.03
A8: Neutral | C8: 0.05 | D8: 0.05 | E8: 0.05 | F8: 0.05 | G8: 0.05 | H8: 0.05
A9: Best | C9: 0.07 | D9: 0.07 | E9: 0.07 | F9: 0.07 | G9: 0.07 | H9: 0.07
A10: Selected (drives model) | C10: =CHOOSE(MATCH('Model Control'!$B$3,{"Worst","Neutral","Best"},0),C7,C8,C9) -> 0.05 | D10: =CHOOSE(MATCH('Model Control'!$B$3,{"Worst","Neutral","Best"},0),D7,D8,D9) -> 0.05 | E10: =CHOOSE(MATCH('Model Control'!$B$3,{"Worst","Neutral","Best"},0),E7,E8,E9) -> 0.05 | F10: =CHOOSE(MATCH('Model Control'!$B$3,{"Worst","Neutral","Best"},0),F7,F8,F9) -> 0.05 | G10: =CHOOSE(MATCH('Model Control'!$B$3,{"Worst","Neutral","Best"},0),G7,G8,G9) -> 0.05 | H10: =CHOOSE(MATCH('Model Control'!$B$3,{"Worst","Neutral","Best"},0),H7,H8,H9) -> 0.05
A12: EMEA Revenue Growth %
A13: EMEA grew 17.2%-17.3% in 2024-2025, aided by the same paid-sharing/ad-tier tailwinds as UCAN, but off a lower penetration base with more runway. Neutral (9%) assumes roughly half the trailing rate persists as the denominator grows and the one-time boost fades. Worst (6%) reflects European macro softness or FX drag on reported USD revenue; Best (12%) assumes penetration gains continue closer to the trailing pace.
A14: Scenario | C14: 2025A | D14: 2026E | E14: 2027E | F14: 2028E | G14: 2029E | H14: 2030E
A15: Worst | C15: 0.06 | D15: 0.06 | E15: 0.06 | F15: 0.06 | G15: 0.06 | H15: 0.06
A16: Neutral | C16: 0.09 | D16: 0.09 | E16: 0.09 | F16: 0.09 | G16: 0.09 | H16: 0.09
A17: Best | C17: 0.12 | D17: 0.12 | E17: 0.12 | F17: 0.12 | G17: 0.12 | H17: 0.12
A18: Selected (drives model) | C18: =CHOOSE(MATCH('Model Control'!$B$3,{"Worst","Neutral","Best"},0),C15,C16,C17) -> 0.09 | D18: =CHOOSE(MATCH('Model Control'!$B$3,{"Worst","Neutral","Best"},0),D15,D16,D17) -> 0.09 | E18: =CHOOSE(MATCH('Model Control'!$B$3,{"Worst","Neutral","Best"},0),E15,E16,E17) -> 0.09 | F18: =CHOOSE(MATCH('Model Control'!$B$3,{"Worst","Neutral","Best"},0),F15,F16,F17) -> 0.09 | G18: =CHOOSE(MATCH('Model Control'!$B$3,{"Worst","Neutral","Best"},0),G15,G16,G17) -> 0.09 | H18: =CHOOSE(MATCH('Model Control'!$B$3,{"Worst","Neutral","Best"},0),H15,H16,H17) -> 0.09
A20: LATAM Revenue Growth %
A21: LATAM grew 8.8%-10.7% in 2024-2025, the slowest major region historically due to price sensitivity and FX volatility (Brazil, Argentina). Neutral (8%) is close to trailing, since LATAM didn't see as large a one-time step-up. Worst (5%) reflects currency devaluation and local-competitor pricing pressure; Best (11%) assumes continued household growth without a major FX shock.
A22: Scenario | C22: 2025A | D22: 2026E | E22: 2027E | F22: 2028E | G22: 2029E | H22: 2030E
A23: Worst | C23: 0.05 | D23: 0.05 | E23: 0.05 | F23: 0.05 | G23: 0.05 | H23: 0.05
A24: Neutral | C24: 0.08 | D24: 0.08 | E24: 0.08 | F24: 0.08 | G24: 0.08 | H24: 0.08
A25: Best | C25: 0.11 | D25: 0.11 | E25: 0.11 | F25: 0.11 | G25: 0.11 | H25: 0.11
A26: Selected (drives model) | C26: =CHOOSE(MATCH('Model Control'!$B$3,{"Worst","Neutral","Best"},0),C23,C24,C25) -> 0.08 | D26: =CHOOSE(MATCH('Model Control'!$B$3,{"Worst","Neutral","Best"},0),D23,D24,D25) -> 0.08 | E26: =CHOOSE(MATCH('Model Control'!$B$3,{"Worst","Neutral","Best"},0),E23,E24,E25) -> 0.08 | F26: =CHOOSE(MATCH('Model Control'!$B$3,{"Worst","Neutral","Best"},0),F23,F24,F25) -> 0.08 | G26: =CHOOSE(MATCH('Model Control'!$B$3,{"Worst","Neutral","Best"},0),G23,G24,G25) -> 0.08 | H26: =CHOOSE(MATCH('Model Control'!$B$3,{"Worst","Neutral","Best"},0),H23,H24,H25) -> 0.08
A28: APAC Revenue Growth %
A29: APAC grew 17.3%-21.3% in 2024-2025, the fastest-accelerating region, off the lowest penetration base (India, Japan, Korea are still under-penetrated). Neutral (12%) assumes deceleration from the 2025 peak as comps normalize, but keeps APAC as the highest-growth region since whitespace is real, not just a one-time conversion effect. Worst (8%) reflects slower India monetization or local-content underperformance; Best (16%) assumes the 2025 pace largely holds.
A30: Scenario | C30: 2025A | D30: 2026E | E30: 2027E | F30: 2028E | G30: 2029E | H30: 2030E
A31: Worst | C31: 0.08 | D31: 0.08 | E31: 0.08 | F31: 0.08 | G31: 0.08 | H31: 0.08
A32: Neutral | C32: 0.12 | D32: 0.12 | E32: 0.12 | F32: 0.12 | G32: 0.12 | H32: 0.12
A33: Best | C33: 0.16 | D33: 0.16 | E33: 0.16 | F33: 0.16 | G33: 0.16 | H33: 0.16
A34: Selected (drives model) | C34: =CHOOSE(MATCH('Model Control'!$B$3,{"Worst","Neutral","Best"},0),C31,C32,C33) -> 0.12 | D34: =CHOOSE(MATCH('Model Control'!$B$3,{"Worst","Neutral","Best"},0),D31,D32,D33) -> 0.12 | E34: =CHOOSE(MATCH('Model Control'!$B$3,{"Worst","Neutral","Best"},0),E31,E32,E33) -> 0.12 | F34: =CHOOSE(MATCH('Model Control'!$B$3,{"Worst","Neutral","Best"},0),F31,F32,F33) -> 0.12 | G34: =CHOOSE(MATCH('Model Control'!$B$3,{"Worst","Neutral","Best"},0),G31,G32,G33) -> 0.12 | H34: =CHOOSE(MATCH('Model Control'!$B$3,{"Worst","Neutral","Best"},0),H31,H32,H33) -> 0.12
A36: Content Spend (Additions) Growth %
A37: Content spend is not separately guided by Netflix, so this is modeled as a rate relative to revenue growth, not an independent estimate. Neutral (10%) tracks below Neutral revenue growth (7-9%), consistent with content spend growing but content cost intensity gradually declining as the library monetizes over more subscribers. Worst (15%) assumes content cost inflation (competitive bidding for sports/marquee titles) outpaces revenue; Best (7%) assumes tighter content ROI discipline.
A38: Scenario | C38: 2025A | D38: 2026E | E38: 2027E | F38: 2028E | G38: 2029E | H38: 2030E
A39: Worst | C39: 0.15 | D39: 0.15 | E39: 0.15 | F39: 0.15 | G39: 0.15 | H39: 0.15
A40: Neutral | C40: 0.1 | D40: 0.1 | E40: 0.1 | F40: 0.1 | G40: 0.1 | H40: 0.1
A41: Best | C41: 0.07 | D41: 0.07 | E41: 0.07 | F41: 0.07 | G41: 0.07 | H41: 0.07
A42: Selected (drives model) | C42: =CHOOSE(MATCH('Model Control'!$B$3,{"Worst","Neutral","Best"},0),C39,C40,C41) -> 0.1 | D42: =CHOOSE(MATCH('Model Control'!$B$3,{"Worst","Neutral","Best"},0),D39,D40,D41) -> 0.1 | E42: =CHOOSE(MATCH('Model Control'!$B$3,{"Worst","Neutral","Best"},0),E39,E40,E41) -> 0.1 | F42: =CHOOSE(MATCH('Model Control'!$B$3,{"Worst","Neutral","Best"},0),F39,F40,F41) -> 0.1 | G42: =CHOOSE(MATCH('Model Control'!$B$3,{"Worst","Neutral","Best"},0),G39,G40,G41) -> 0.1 | H42: =CHOOSE(MATCH('Model Control'!$B$3,{"Worst","Neutral","Best"},0),H39,H40,H41) -> 0.1
A44: Cost of Revenues (% of Revenue)
A45: Cost of revenue was 51.5% of revenue in 2025A (2025A cell is now a live formula, not hardcoded, so it can never drift from the historicals again). Netflix has publicly guided toward continued operating margin expansion as the platform scales. Neutral assumes ~25-30bps/year of leverage (51.5% to ~50.0% by 2030). Worst assumes leverage stalls and the ratio drifts up (~52.5% by 2030) from content-cost inflation or competitive spend; Best assumes leverage accelerates (~48.3%) if ad-tier and live content scale efficiently against largely fixed platform costs.
A46: Scenario | C46: 2025A | D46: 2026E | E46: 2027E | F46: 2028E | G46: 2029E | H46: 2030E
...

Sheet P&L Input
A1: P&L Statement | E1: (in thousands, except per share data)
C2: 2023 | D2: 2024 | E2: 2025
A3: Revenues | C3: 33723297 | D3: 39000966 | E3: 45183036
A4: Cost of revenues | C4: 19715368 | D4: 21038464 | E4: 23275329
C5: =C3-C4 -> 14007929 | D5: =D3-D4 -> 17962502 | E5: =E3-E4 -> 21907707
A6: Sales and marketing | C6: 2657883 | D6: 2917554 | E6: 3301306
A7: Technology and development | C7: 2675758 | D7: 2925295 | E7: 3391390
A8: General and administrative | C8: 1720285 | D8: 1702039 | E8: 1888408
A9: Operating income | C9: =C5-C6-C7-C8 -> 6954003 | D9: =D5-D6-D7-D8 -> 10417614 | E9: =E5-E6-E7-E8 -> 13326603
A10: Other income (expense):
A11: Interest expense | C11: -699826 | D11: -718733 | E11: -776510
A12: Interest and other income (expense) | C12: -48772 | D12: 266776 | E12: 172459
A13: Income before income taxes | C13: =C9+C11+C12 -> 6205405 | D13: =D9+D11+D12 -> 9965657 | E13: =E9+E11+E12 -> 12722552
A14: Provision for income taxes | C14: -797415 | D14: -1254026 | E14: -1741351
A15: Net income | C15: =SUM(C13:C14) -> 5407990 | D15: =D13+D14 -> 8711631 | E15: =E13+E14 -> 10981201
A17: Earnings per share:
A18: Basic | C18: 1.22 | D18: 2.03 | E18: 2.58
A19: Diluted | C19: 1.2 | D19: 1.98 | E19: 2.53
A20: Weighted-average shares of common stock outstanding:
A21: Basic | C21: 4,415,712 | D21: 4,295,191 | E21: 4,249,512
A22: Diluted | C22: 4,494,966 | D22: 4,392,608 | E22: 4,343,863
A25: Net income | C25: =C15 -> 5407990 | D25: =D15 -> 8711631 | E25: =E15 -> 10981201
A26: Other comprehensive income (loss):
A27: Foreign currency translation adjustments, net of income tax benefit (expense) of $33 million, $(7) million, and $0, respectively | C27: 113384 | D27: -247949 | E27: 72011
A28: Net change in unrealized gains (losses) on available-for-sale securities, net of income tax benefit (expense) of $1 million, $(1) million, and $0, respectively | D28: 2511 | E28: -2511
A29: Cash flow hedges:
A30: Net unrealized gains (losses) | C30: -120023 | D30: 921227 | E30: -1071168
A31: Reclassification of net (gains) losses included in net income | D31: -96795 | E31: 68962
A32: Net change, net of income tax benefit (expense) of $301 million, $(246) million, and $36 million, respectively | C32: =SUM(C30:C31) -> -120023 | D32: =SUM(D30:D31) -> 824432 | E32: =SUM(E30:E31) -> -1002206
A33: Fair value hedges:
A34: Net change in unrealized gains (losses) excluded from the assessment of effectiveness, net of income tax benefit (expense) of $3 million, $(2) million, and $0, respectively | D34: 7113 | E34: -9838
A35: Total other comprehensive income (loss) | C35: =C27+C28+C32+C34 -> -6639 | D35: =D27+D28+D32+D34 -> 586107 | E35: =E27+E28+E32+E34 -> -942544
A36: Comprehensive income | C36: =C25+C35 -> 5401351 | D36: =D25+D35 -> 9297738 | E36: =E25+E35 -> 10038657

Sheet Balance Sheet Input
A1: Balance Sheet | E1: in thousands, except share and per share data
B3: 2023 | C3: 2024 | D3: 2025
A4: Assets
A5: Current assets:
A6: Cash and cash equivalents | B6: 7116913 | C6: 7804733 | D6: 9033681 | F6: Cashflow
A7: Short-term investments | B7: 20973 | C7: 1779006 | D7: 28678
A8: Other current assets | B8: 2780247 | C8: 3516640 | D8: 3957832 | F8: Other Items
A9: Total current assets | B9: =SUM(B6:B8) -> 9918133 | C9: =SUM(C6:C8) -> 13100379 | D9: =SUM(D6:D8) -> 13020191
A10: Content assets, net | B10: 31658056 | C10: 32452462 | D10: 32778392 | F10: Schedules
A11: Property and equipment, net | B11: 1491444 | C11: 1593756 | D11: 2004350 | F11: Schedules
A12: Other non-current assets | B12: 5664359 | C12: 6483777 | D12: 7794060
A13: Total assets | B13: =SUM(B9:B12) -> 48731992 | C13: =SUM(C9:C12) -> 53630374 | D13: =SUM(D9:D12) -> 55596993
A15: Liabilities and Stockholders' Equity
A16: Current liabilities:
A17: Current content liabilities | B17: 4466470 | C17: 4393681 | D17: 4084854
A18: Accounts payable | B18: 747412 | C18: 899909 | D18: 900612 | F18: Other Items
A19: Accrued expenses and other liabilities | B19: 1803960 | C19: 2156544 | D19: 3220869
A20: Deferred revenue | B20: 1442969 | C20: 1520813 | D20: 1775730
A21: Short-term debt | B21: 399844 | C21: 1784453 | D21: 998865
A22: Total current liabilities | B22: =SUM(B17:B21) -> 8860655 | C22: =SUM(C17:C21) -> 10755400 | D22: =SUM(D17:D21) -> 10980930
A23: Non-current content liabilities | B23: 2578173 | C23: 1780806 | D23: 1579476
A24: Long-term debt | B24: 14143417 | C24: 13798351 | D24: 13463971
A25: Other non-current liabilities | B25: 2561434 | C25: 2552250 | D25: 2957128
A26: Total liabilities | B26: =SUM(B22:B25) -> 28143679 | C26: =SUM(C22:C25) -> 28886807 | D26: =SUM(D22:D25) -> 28981505
A27: Stockholders' equity:
A28: Common stock | B28: 5145172 | C28: 6252126 | D28: 7286410
A29: Treasury stock | B29: -6922200 | C29: -13171638 | D29: -22372658
A30: Accumulated other comprehensive income (loss) | B30: -223945 | C30: 362162 | D30: -580382
A31: Retained earnings | B31: 22589286 | C31: 31300917 | D31: 42282118
A32: Total stockholders' equity | B32: =SUM(B28:B31) -> 20588313 | C32: =SUM(C28:C31) -> 24743567 | D32: =SUM(D28:D31) -> 26615488
A33: Total liabilities and stockholders' equity | B33: =B26+B32 -> 48731992 | C33: =C26+C32 -> 53630374 | D33: =D26+D32 -> 55596993

Sheet CFS Input
A1: Cash Flow Statement (USD in thousands) | B1: 2023 | C1: 2024 | D1: 2025
A3: Cash flows from operating activities
A4: Net income | B4: 5407990 | C4: 8711631 | D4: 10981201
A5: Adjustments to reconcile net income to net cash provided by operating activities
A6: Additions to content assets | B6: -12554703 | C6: -16223617 | D6: -17096617
A7: Change in content liabilities | B7: -585602 | C7: -779135 | D7: -610838
A8: Amortization of content assets | B8: 14197437 | C8: 15301517 | D8: 16422166
A9: Depreciation and amortization of property, equipment and intangibles | B9: 356947 | C9: 328914 | D9: 333389
A10: Stock-based compensation expense | B10: 339368 | C10: 272588 | D10: 368449
A11: Foreign currency remeasurement loss (gain) on debt | B11: 176296 | C11: -121539 | D11: 72348
A12: Other non-cash items | B12: 512075 | C12: 494778 | D12: 577451
A13: Deferred income taxes | B13: -459359 | C13: -590698 | D13: -442056
A14: Changes in operating assets and liabilities
A15: Other current assets | B15: -181003 | C15: 22180 | D15: -790661
A16: Accounts payable | B16: 93502 | C16: 121353 | D16: -8039
A17: Accrued expenses and other liabilities | B17: 103565 | C17: 191899 | D17: 881218
A18: Deferred revenue | B18: 178708 | C18: 77844 | D18: 254917
A19: Other non-current assets and liabilities | B19: -310920 | C19: -446351 | D19: -793655
A20: Net cash provided by operating activities | B20: =SUM(B4:B19) -> 7274301 | C20: =SUM(C4:C19) -> 7361364 | D20: =SUM(D4:D19) -> 10149273
A22: Cash flows from investing activities
A23: Purchases of property and equipment | B23: -348552 | C23: -439538 | D23: -688220
A24: Acquisitions | B24: 0 | C24: 0 | D24: -17194
A25: Purchase of Investments | B25: -504862 | C25: -1742246 | D25: -169965
A26: Proceeds from maturities and sales of invesments | B26: 1395165 | C26: 0 | D26: 1917067
A27: Net cash provided by (used in) used in investing activities | B27: =SUM(B23:B26) -> 541751 | C27: =SUM(C23:C26) -> -2181784 | D27: =SUM(D23:D26) -> 1041688
A29: Cash flows from financing activities
A30: Proceeds from issuance of debt | B30: 0 | C30: 1794460 | D30: 0
A31: Repayment of debt | B31: 0 | C31: -400000 | D31: -1833450
A32: Proceeds from issuance of common stock | B32: 169990 | C32: 832887 | D32: 666965
A33: Repurchases of common stock | B33: -6045347 | C33: -6263746 | D33: -9127167
A34: Taxes paid related to net share settlement of equity awards | B34: 0 | C34: -8285 | D34: -46165
A35: Other financing activities | B35: -75446 | C35: -29743 | D35: -5806
A36: Net cash provided by (used in) financing activities | B36: =SUM(B30:B35) -> -5950803 | C36: =SUM(C30:C35) -> -4074427 | D36: =SUM(D30:D35) -> -10345623
A38: Effect of exchange rate changes on cash, cash equivalents and restricted cash | B38: 82684 | C38: -416331 | D38: 386519
A39: Net increase (decrease) in cash, cash equivalents and restricted cash | B39: =B20+B27+B36+B38 -> 1947933 | C39: =C20+C27+C36+C38 -> 688822 | D39: =D20+D27+D36+D38 -> 1231857
A41: Cash, cash equivalents and restricted cash at beginning of year | B41: 5170582 | C41: 7118515 | D41: 7807337
A42: Cash, cash equivalents and restricted cash at end of year | B42: =B39+B41 -> 7118515 | C42: =C39+C41 -> 7807337 | D42: =D39+D41 -> 9039194
A44: Supplemental disclosure
A45: Interest paid | B45: 684504 | C45: 674502 | D45: 718611

Sheet Revenue Modelling
A1: Revenue Sources
A3: Streaming revenues | B3: 2023 | C3: 2024 | D3: 2025
A4: United States and Canada (UCAN) | B4: 14873783 | C4: 17359369 | D4: 19957152
A5: Growth percentage | C5: =(C4-B4)/B4 -> 0.16711189 | D5: =(D4-C4)/C4 -> 0.14964732
A6: Europe, Middle East, and Africa (EMEA) | B6: 10556487 | C6: 12387035 | D6: 14514646
A7: Growth percentage | C7: =(C6-B6)/B6 -> 0.17340504 | D7: =(D6-C6)/C6 -> 0.17176112
A8: Latin America (LATAM) | B8: 4446461 | C8: 4839816 | D8: 5357521
A9: Growth percentage | C9: =(C8-B8)/B8 -> 0.088464736 | D9: =(D8-C8)/C8 -> 0.10696791
A10: Asia-Pacific (APAC) | B10: 3763727 | C10: 4414746 | D10: 5353717
A11: Growth percentage | C11: =(C10-B10)/B10 -> 0.1729719 | D11: =(D10-C10)/C10 -> 0.2126897
A12: Total Streaming Revenues | B12: 33640458 | C12: 39000966 | D12: 45183036
A13: Total growth percentage | C13: =(C12-B12)/B12 -> 0.15934706 | D13: =(D12-C12)/C12 -> 0.15851069
A15: DVD | B15: 82839
A17: Total Revenue | B17: 33723297 | C17: 39000966 | D17: 45183036
A19: Additional Points
A21: 1. Netflix discontinued DVD-by-mail service in the year ended December 31, 2023. The discontinuance of our DVD business had an immaterial impact on operations and financial results
A23: 2. During the year ended December 31, 2025, we discontinued the reporting of membership numbers, including average paying memberships and average monthly revenue per paying membership, focusing instead on revenue and operating margin as the primary financial metrics that we believe best represent our business performance.

Sheet Other Items
A1: Other Items
E2: Forecasted
A3: (in thousands) | B3: 2023 | C3: 2024 | D3: 2025 | E3: 2026 | F3: 2027 | G3: 2028 | H3: 2029
A4: Cost of Goods Sold | B4: ='P&L Input'!C4 -> 19715368 | C4: ='P&L Input'!D4 -> 21038464 | D4: ='P&L Input'!E4 -> 23275329
A5: Adjustment (See Note Below) | B5: 0 | C5: 0 | D5: -1116000
A6: COGS under normal business environment | B6: =SUM(B4:B5) -> 19715368 | C6: =SUM(C4:C5) -> 21038464 | D6: =SUM(D4:D5) -> 22159329
A7: as a % revenues | B7: =B6/'P&L Input'!C3 -> 0.5846216 | C7: =C6/'P&L Input'!D3 -> 0.53943443 | D7: =D6/'P&L Input'!E3 -> 0.49043471
A8: Increase % | C8: =(C6-B6)/B6 -> 0.067109881 | D8: =(D6-C6)/C6 -> 0.053276941
A9: Cost of revenues forecast based on normalized historical trends adjusted for expected operating leverage and scalability of streaming operations.
A10: The increase in cost of revenues for the year ended December 31, 2025 as compared to the year ended December 31, 2024 was primarily due to a $1,121 million increase in content amortization relating to our existing and new content, coupled with a $1,116 million increase in other cost of revenues, primarily driven by non-income tax assessments in Brazil. We do not expect that non-income taxes incurred in Brazil will materially impact our results of operations in future periods. See Note 9 Commitments and Contingencies in the accompanying notes to our consolidated financial statements for further detail on our non-income tax matters.
A12: Marketing | B12: ='P&L Input'!C6 -> 2657883 | C12: ='P&L Input'!D6 -> 2917554 | D12: ='P&L Input'!E6 -> 3301306
A13: as a % revenues | B13: =B12/'P&L Input'!C$3 -> 0.078814447 | C13: =C12/'P&L Input'!D$3 -> 0.074807224 | D13: =D12/'P&L Input'!E$3 -> 0.073065165
A14: Increase % | C14: =(C12-B12)/B12 -> 0.097698431 | D14: =(D12-C12)/C12 -> 0.1315321
A15: The increase in sales and marketing expenses for the year ended December 31, 2025 as compared to the year ended December 31, 2024 was primarily driven by a $222 million increase in marketing expenses, coupled with a $149 million increase in personnel-related costs due to the growth in advertising sales headcount.
A17: Technology and Development | B17: ='P&L Input'!C7 -> 2675758 | C17: ='P&L Input'!D7 -> 2925295 | D17: ='P&L Input'!E7 -> 3391390
A18: as a % revenues | B18: =B17/'P&L Input'!C$3 -> 0.079344496 | C18: =C17/'P&L Input'!D$3 -> 0.075005706 | D18: =D17/'P&L Input'!E$3 -> 0.075058923
A19: Increase % | C19: =(C17-B17)/B17 -> 0.093258434 | D19: =(D17-C17)/C17 -> 0.15933265
A20: The increase in technology and development expenses for the year ended December 31, 2025 as compared to the year ended December 31, 2024 was primarily due to a $438 million increase in personnel-related costs.
A22: General and Administrative | B22: ='P&L Input'!C8 -> 1720285 | C22: ='P&L Input'!D8 -> 1702039 | D22: ='P&L Input'!E8 -> 1888408
A23: as a % revenues | B23: =B22/'P&L Input'!C$3 -> 0.051011768 | C23: =C22/'P&L Input'!D$3 -> 0.043640945 | D23: =D22/'P&L Input'!E$3 -> 0.041794624
A24: Increase % | C24: =(C22-B22)/B22 -> -0.010606382 | D24: =(D22-C22)/C22 -> 0.10949749
A25: The increase in general and administrative expenses for the year ended December 31, 2025 as compared to the year ended December 31, 2024 was primarily due to a $92 million increase in personnel-related costs and a $64 million increase in third-party expenses. The increase in personnel-related costs was primarily driven by higher share-based compensation expense, while the increase in third-party expenses was attributable to higher legal fees and transaction-related costs, including those associated with the WBD transaction.
A27: Other Current assets | B27: ='Balance Sheet Input'!B8 -> 2780247 | C27: ='Balance Sheet Input'!C8 -> 3516640 | D27: ='Balance Sheet Input'!D8 -> 3957832
A28: as a % revenues | B28: =B27/'P&L Input'!C3 -> 0.082442918 | C28: =C27/'P&L Input'!D3 -> 0.090168023 | D28: =D27/'P&L Input'!E3 -> 0.08759553
A29: Increase % | C29: =(C27-B27)/B27 -> 0.26486604 | D29: =(D27-C27)/C27 -> 0.12545839
A30: Accounts Payable | B30: ='Balance Sheet Input'!B18 -> 747412 | C30: ='Balance Sheet Input'!C18 -> 899909 | D30: ='Balance Sheet Input'!D18 -> 900612
A31: Days Payable | B31: =(B30/B4)*365 -> 13.837194 | C31: =(C30/C4)*365 -> 15.612679 | D31: =(D30/D4)*365 -> 14.123254
A32: Increase % | C32: =(C30-B30)/B30 -> 0.20403338 | D32: =(D30-C30)/C30 -> 0.0007811901
A33: Accrued Expenses and other Liabilities | B33: ='Balance Sheet Input'!B19 -> 1803960 | C33: ='Balance Sheet Input'!C19 -> 2156544 | D33: ='Balance Sheet Input'!D19 -> 3220869
A34: as a % revenues | B34: =B33/'P&L Input'!C3 -> 0.05349299 | C34: =C33/'P&L Input'!D3 -> 0.05529463 | D34: =D33/'P&L Input'!E3 -> 0.071284918
A35: Increase % | C35: =(C33-B33)/B33 -> 0.19545001 | D35: =(D33-C33)/C33 -> 0.49353271
A36: Deferred Revenue | B36: ='Balance Sheet Input'!B20 -> 1442969 | C36: ='Balance Sheet Input'!C20 -> 1520813 | D36: ='Balance Sheet Input'!D20 -> 1775730
A37: as a % revenues | B37: =B36/'P&L Input'!C3 -> 0.042788491 | C37: =C36/'P&L Input'!D3 -> 0.038994239 | D37: =D36/'P&L Input'!E3 -> 0.039300812
A38: Increase % | C38: =(C36-B36)/B36 -> 0.053947105 | D38: =(D36-C36)/C36 -> 0.1676189
A39: Interest Expense | B39: ='P&L Input'!C11 -> -699826 | C39: ='P&L Input'!D11 -> -718733 | D39: ='P&L Input'!E11 -> -776510
A40: as a % revenues | B40: =B39/'P&L Input'!C$3 -> -0.020752004 | C40: =C39/'P&L Input'!D$3 -> -0.018428595 | D40: =D39/'P&L Input'!E$3 -> -0.017185875
A41: Increase % | C41: =(C39-B39)/B39 -> 0.027016716 | D41: =(D39-C39)/C39 -> 0.080387293
A42: Interest expense primarily consists of interest on our Notes of $716 million for the year ended December 31, 2025. The increase in interest expense for the year ended December 31, 2025 as compared to the year ended December 31, 2024 was primarily driven by higher amortization of debt issuance costs, including approximately $60 million related to financing arrangements entered into in connection with the WBD transaction. See Note 7 Debt for additional details regarding the financing arrangements associated with the WBD transaction.
A44: Interest and Other Income (Expense) | B44: ='P&L Input'!C12 -> -48772 | C44: ='P&L Input'!D12 -> 266776 | D44: ='P&L Input'!E12 -> 172459
A45: as a % revenues | B45: =B44/'P&L Input'!C$3 -> -0.0014462406 | C45: =C44/'P&L Input'!D$3 -> 0.0068402408 | D45: =D44/'P&L Input'!E$3 -> 0.0038168971
...

Sheet Schedules
A1: PP&E
A3: (in thousands) | B3: 2023 | C3: 2024 | D3: 2025
A4: Beginning Balance | C4: =B7 -> 1491444 | D4: =C7 -> 1593756
A5: add: Capex | C5: =C7+C6-C4 -> 205891 | D5: =D7+D6-D4 -> 526304
A6: less: Depreciation | B6: 83157 | C6: 103579 | D6: 115710
A7: Closing Balance | B7: ='Balance Sheet Input'!B11 -> 1491444 | C7: ='Balance Sheet Input'!C11 -> 1593756 | D7: ='Balance Sheet Input'!D11 -> 2004350
A9: Useful life | C9: =(C4+C5)/C6 -> 16.386864 | D9: =(D4+D5)/D6 -> 18.322185
A12: Content Assets
A13: (in thousands) | B13: 2023 | C13: 2024 | D13: 2025
A14: Beginning Balance | C14: =B17 -> 31658056 | D14: =C17 -> 32452462
A15: add: Addition to Content Assets | C15: =C17+C16-C14 -> 10010653 | D15: =D17+D16-D14 -> 11132842
A16: less: Amortisation of Content Assets | C16: 9216247 | D16: 10806912
A17: Closing Balance | B17: ='Balance Sheet Input'!B10 -> 31658056 | C17: ='Balance Sheet Input'!C10 -> 32452462 | D17: ='Balance Sheet Input'!D10 -> 32778392
A19: Useful life | C19: =(C14+C15)/C16 -> 4.5212231 | D19: =(D14+D15)/D16 -> 4.0330951
A22: Debt Schedule
A23: Beginning Balance of Debt | C23: =B25 -> 14143417 | D23: =C25 -> 13798351
A24: add/less: Debt Taken /(debt repaid) | C24: =C25-C23 -> -345066 | D24: =D25-D23 -> -334380
A25: Closing Balance | B25: ='Balance Sheet Input'!B24 -> 14143417 | C25: ='Balance Sheet Input'!C24 -> 13798351 | D25: ='Balance Sheet Input'!D24 -> 13463971
A27: Interest Expense | B27: ='P&L Input'!C11 -> -699826 | C27: ='P&L Input'!D11 -> -718733 | D27: ='P&L Input'!E11 -> -776510
B28: =B27/B25 -> -0.049480688 | C28: =C27/C25 -> -0.052088326 | D28: =D27/D25 -> -0.057673178
A31: Content Assets, Net
A32: As of December 31, 2025, approximately $6,381 million, $2,280 million, and $1,469 million of the $12,139 million unamortized cost of the licensed content is expected to be amortized in each of the next three years. As of December 31, 2025, approximately $4,309 million, $2,784 million, and $1,840 million of the $10,687 million unamortized cost of the produced content that has been released is expected to be amortized in each of the next three years.
A34: Licensed content net | C34: 12422309 | D34: 12138578
A36: Produced content net
A37: Released less amort | C37: 10151543 | D37: 10687444
A38: in prod | C38: 9317367 | D38: 9210735
A39: in development and pre-prod | C39: 561243 | D39: 741635
C40: =SUM(C37:C39) -> 20030153 | D40: =SUM(D37:D39) -> 20639814
A42: Content assets, net | C42: =C34+C40 -> 32452462 | D42: =D34+D40 -> 32778392
A44: Amortisation | B44: 2023 | C44: 2024 | D44: 2025
A45: Licensed content | B45: 7145446 | C45: 7689014 | D45: 8713558
A46: Produced content | B46: 7051991 | C46: 7612503 | D46: 7708608
B47: =SUM(B45:B46) -> 14197437 | C47: =SUM(C45:C46) -> 15301517 | D47: =SUM(D45:D46) -> 16422166
A52: Content Assets
A53: (in thousands) | B53: 2023 | C53: 2024 | D53: 2025
A54: Beginning Balance | B54: =B56+B57 -> 45855493 | C54: =B57 -> 31658056 | D54: =C57 -> 32452462
A55: add: Addition to Content Assets | B55: =B57-B54+B56 -> 0 | C55: =C57-C54+C56 -> 16095923 | D55: =D57-D54+D56 -> 16748096
A56: less: Amortisation of Content Assets | B56: =B47 -> 14197437 | C56: =C47 -> 15301517 | D56: =D47 -> 16422166
A57: Closing Balance | B57: 31658056 | C57: =C42 -> 32452462 | D57: =D42 -> 32778392
A59: Useful life | D59: `
...

Sheet Debt
A1: Netflix, Inc. — Senior Notes Detail
A2: As of December 31, 2025 | US$ in thousands (euro face shown in €) | Source: FY2025 Form 10-K, Note 7 Debt (SEC accession 0001065280-26-000034, filed 2026-01-23)
A4: As of December 31, 2025, the Company had aggregate outstanding notes of $14,463 million, net of $56 million of issuance costs and discounts, with varying maturities (the “Notes”). As of December 31, 2024, the Company had aggregate outstanding notes of $15,583 million, net of $70 million of issuance costs and discounts. Each of the Notes are senior unsecured obligations of the Company. Interest is payable semi-annually at fixed rates. A portion of the outstanding Notes is denominated in foreign currency (comprised of €4,700 million) and is remeasured into U.S. dollars at each balance sheet date (with remeasurement loss, net of hedging impacts, totaling $72 million for the year ended December 31, 2025). See Note 8 Derivative Financial Instruments and Hedging Activities to the consolidated financial statements for further information regarding the Company’s derivative and non-derivative financial instruments.
A6: The following table provides a summary of the Company's outstanding debt and the fair values based on quoted market prices in less active markets as of December 31, 2025 and December 31, 2024:
B8: Principal Amount at Par
A9: Senior Notes | B9: Dec 31 2025 | C9: Dec 31 2026 | D9: Issuance Date | E9: Maturity | F9: Level 2 Fair Value (2025) | G9: Level 2 Fair Value (2024)
A10: 5.875% Senior Notes | B10: 0 | C10: 800 | D10: 42036 | E10: 45689 | F10: 0 | G10: 801
A11: 3.000% Senior Notes | B11: 0 | C11: 487 | D11: 43922 | E11: 45809 | F11: 0 | G11: 487
A12: 3.625% Senior Notes | B12: 0 | C12: 500 | D12: 43922 | E12: 45809 | F12: 0 | G12: 497
A13: 4.375% Senior Notes | B13: 1000 | C13: 1000 | D13: 42644 | E13: 46327 | F13: 1006 | G13: 998
A14: 3.625% Senior Notes | B14: 1526 | C14: 1346 | D14: 42856 | E14: 46508 | F14: 1550 | G14: 1375
A15: 4.875% Senior Notes | B15: 1600 | C15: 1600 | D15: 43009 | E15: 46844 | F15: 1634 | G15: 1607
A16: 5.875% Senior Notes | B16: 1900 | C16: 1900 | D16: 43191 | E16: 47058 | F16: 1998 | G16: 1970
A17: 4.625% Senior Notes | B17: 1292 | C17: 1139 | D17: 43374 | E17: 47239 | F17: 1363 | G17: 1220
A18: 6.375% Senior Notes | B18: 800 | C18: 800 | D18: 43374 | E18: 47239 | F18: 857 | G18: 848
A19: 3.875% Senior Notes | B19: 1409 | C19: 1242 | D19: 43556 | E19: 47423 | F19: 1455 | G19: 1293
A20: 5.375% Senior Notes | B20: 900 | C20: 900 | D20: 43556 | E20: 47423 | F20: 939 | G20: 918
A21: 3.625% Senior Notes | B21: 1292 | C21: 1139 | D21: 43739 | E21: 47635 | F21: 1322 | G21: 1174
... A24: 5.400% Senior Notes | B24: 800 | C24: 800 | D24: 45505 | E24: 56462 | F24: 777 | G24: 782
A25: Total | B25: =SUM(B10:B24) -> 14519 | C25: =SUM(C10:C24) -> 15653 | F25: =SUM(F10:F24) -> 14951 | G25: =SUM(G10:G24) -> 15948
A27: 1. The following Senior Notes have a principal amount denominated in Euro: 3.000% Senior Notes for €470 million, 3.625% Senior Notes for €1,300 million, 4.625% Senior Notes for €1,100 million, 3.875% Senior Notes for €1,200 million, and 3.625% Senior Notes for €1,100 million.
A28: In the year ended December 31, 2025, the Company repaid upon maturity the $800 million aggregate principal amount of its 5.875% Senior Notes, the €470 million aggregate principal amount of its 3.000% Senior Notes, and the $500 million aggregate principal amount of its 3.625% Senior Notes.
A29: Each of the Notes are repayable in whole or in part upon the occurrence of a change of control, at the option of the holders, at a purchase price in cash equal to 101% of the principal plus accrued interest. The Company may redeem the Notes prior to maturity in whole or in part at an amount equal to the principal amount thereof plus accrued and unpaid interest and an applicable premium. The Notes include, among other terms and conditions, limitations on the Company's ability to create, incur or allow certain liens, and consolidate or merge with, or convey, transfer or lease all or substantially all of the Company's and its subsidiaries assets, to another person. Certain of the Notes additionally limit the ability to enter into sale and lease-back transactions and create, assume, incur or guarantee additional indebtedness of certain of the Company's subsidiaries. As of December 31, 2025 and December 31, 2024, the Company was in compliance with all related covenants.
A32: EUR/USD year-end rate (assumption — confirm to 10-K): | D32: 1.176 | E32: <- adjust so euro USD-equivalents tie to Note 7
A34: Series (Senior Notes) | B34: Currency | C34: Coupon | D34: Face / Principal (in currency) | E34: Maturity Date | F34: Maturity Year | G34: Face in USD (computed) | H34: Fair Value (per 10-K)
A35: 4.375% Senior Notes | B35: USD | C35: 0.04375 | D35: 1000000 | E35: Nov 15, 2026 | F35: 2026 | G35: =IF(B35="EUR",D35*1.176,D35) -> 1000000 | H35: 1006000
A36: 3.625% Senior Notes | B36: EUR | C36: 0.03625 | D36: 1300000 | E36: May 15, 2027 | F36: 2027 | G36: =IF(B36="EUR",D36*1.176,D36) -> 1528800 | H36: 1550000
A37: 4.875% Senior Notes | B37: USD | C37: 0.04875 | D37: 1600000 | E37: Apr 15, 2028 | F37: 2028 | G37: =IF(B37="EUR",D37*1.176,D37) -> 1600000 | H37: 1634000
A38: 5.875% Senior Notes | B38: USD | C38: 0.05875 | D38: 1900000 | E38: Nov 15, 2028 | F38: 2028 | G38: =IF(B38="EUR",D38*1.176,D38) -> 1900000 | H38: 1998000
A39: 6.375% Senior Notes | B39: USD | C39: 0.06375 | D39: 800000 | E39: May 15, 2029 | F39: 2029 | G39: =IF(B39="EUR",D39*1.176,D39) -> 800000 | H39: 857000
A40: 4.625% Senior Notes | B40: EUR | C40: 0.04625 | D40: 1100000 | E40: May 15, 2029 | F40: 2029 | G40: =IF(B40="EUR",D40*1.176,D40) -> 1293600 | H40: 1363000
A41: 3.875% Senior Notes | B41: EUR | C41: 0.03875 | D41: 1200000 | E41: Nov 15, 2029 | F41: 2029 | G41: =IF(B41="EUR",D41*1.176,D41) -> 1411200 | H41: 1455000
A42: 5.375% Senior Notes | B42: USD | C42: 0.05375 | D42: 900000 | E42: Nov 15, 2029 | F42: 2029 | G42: =IF(B42="EUR",D42*1.176,D42) -> 900000 | H42: 939000
A43: 3.625% Senior Notes | B43: EUR | C43: 0.03625 | D43: 1100000 | E43: Jun 15, 2030 | F43: 2030 | G43: =IF(B43="EUR",D43*1.176,D43) -> 1293600 | H43: 1322000
A44: 4.875% Senior Notes | B44: USD | C44: 0.04875 | D44: 1000000 | E44: Jun 15, 2030 | F44: 2030 | G44: =IF(B44="EUR",D44*1.176,D44) -> 1000000 | H44: 1025000
A45: 4.90% Senior Notes | B45: USD | C45: 0.049 | D45: 1000000 | E45: Aug 15, 2034 | F45: 2034 | G45: =IF(B45="EUR",D45*1.176,D45) -> 1000000 | H45: 1025000
A46: 5.40% Senior Notes | B46: USD | C46: 0.054 | D46: 800000 | E46: Aug 15, 2054 | F46: 2054 | G46: =IF(B46="EUR",D46*1.176,D46) -> 800000 | H46: 777000
A47: Total aggregate principal | D47: =SUMIF(B35:B46,"USD",D35:D46) -> 9000000 | G47: =SUM(G35:G46) -> 14527200 | H47: =SUM(H35:H46) -> 14951000
A48: of which euro-denominated (€): | D48: =SUMIF(B35:B46,"EUR",D35:D46) -> 4700000
A50: Reconciliation to balance-sheet carrying amounts (per 10-K):
...

Sheet Proj Drivers
A1: Projection Drivers — resolved from selected scenario
A3: (links into Assumptions tab via the scenario switch) | B3: 2025A | C3: 2026E | D3: 2027E | E3: 2028E | F3: 2029E | G3: 2030E
A5: Cost of revenues (% rev) | B5: =Assumptions!C50 -> 0.51513424 | C5: =Assumptions!D50 -> 0.512134 | D5: =Assumptions!E50 -> 0.509134 | E5: =Assumptions!F50 -> 0.506134 | F5: =Assumptions!G50 -> 0.503134 | G5: =Assumptions!H50 -> 0.500134
A6: Sales & marketing (% rev) | B6: =Assumptions!C58 -> 0.073065165 | C6: =Assumptions!D58 -> 0.072065 | D6: =Assumptions!E58 -> 0.071065 | E6: =Assumptions!F58 -> 0.070065 | F6: =Assumptions!G58 -> 0.069065 | G6: =Assumptions!H58 -> 0.068065
A7: Technology & dev (% rev) | B7: =Assumptions!C66 -> 0.075058923 | C7: =Assumptions!D66 -> 0.075059 | D7: =Assumptions!E66 -> 0.074059 | E7: =Assumptions!F66 -> 0.073059 | F7: =Assumptions!G66 -> 0.072059 | G7: =Assumptions!H66 -> 0.071059
A8: General & admin (% rev) | B8: =Assumptions!C74 -> 0.041794624 | C8: =Assumptions!D74 -> 0.040795 | D8: =Assumptions!E74 -> 0.039795 | E8: =Assumptions!F74 -> 0.038795 | F8: =Assumptions!G74 -> 0.037795 | G8: =Assumptions!H74 -> 0.036795
A9: Other current assets (% rev) | B9: =Assumptions!C82 -> 0.08759553 | C9: =Assumptions!D82 -> 0.087596 | D9: =Assumptions!E82 -> 0.086596 | E9: =Assumptions!F82 -> 0.085596 | F9: =Assumptions!G82 -> 0.084596 | G9: =Assumptions!H82 -> 0.083596
A10: Days payable outstanding | B10: =Assumptions!C90 -> 14.1 | C10: =Assumptions!D90 -> 14.2 | D10: =Assumptions!E90 -> 14.3 | E10: =Assumptions!F90 -> 14.4 | F10: =Assumptions!G90 -> 14.5 | G10: =Assumptions!H90 -> 14.5
A11: Accrued expenses (% rev) | B11: =Assumptions!C98 -> 0.071284918 | C11: =Assumptions!D98 -> 0.070285 | D11: =Assumptions!E98 -> 0.069285 | E11: =Assumptions!F98 -> 0.068285 | F11: =Assumptions!G98 -> 0.067285 | G11: =Assumptions!H98 -> 0.066285
A12: Deferred revenue (% rev) | B12: =Assumptions!C106 -> 0.039300812 | C12: =Assumptions!D106 -> 0.039301 | D12: =Assumptions!E106 -> 0.039301 | E12: =Assumptions!F106 -> 0.038301 | F12: =Assumptions!G106 -> 0.038301 | G12: =Assumptions!H106 -> 0.037301
A13: Interest & other income (expense) | B13: =Assumptions!C114 -> 172459 | C13: =Assumptions!D114 -> 50000 | D13: =Assumptions!E114 -> 75000 | E13: =Assumptions!F114 -> 100000 | F13: =Assumptions!G114 -> 100000 | G13: =Assumptions!H114 -> 125000
A14: Effective tax rate | B14: =Assumptions!C122 -> 0.1368712 | C14: =Assumptions!D122 -> 0.136871 | D14: =Assumptions!E122 -> 0.136871 | E14: =Assumptions!F122 -> 0.136871 | F14: =Assumptions!G122 -> 0.136871 | G14: =Assumptions!H122 -> 0.136871
A16: UCAN revenue growth | B16: =Assumptions!C10 -> 0.05 | C16: =Assumptions!D10 -> 0.05 | D16: =Assumptions!E10 -> 0.05 | E16: =Assumptions!F10 -> 0.05 | F16: =Assumptions!G10 -> 0.05 | G16: =Assumptions!H10 -> 0.05
A17: EMEA revenue growth | B17: =Assumptions!C18 -> 0.09 | C17: =Assumptions!D18 -> 0.09 | D17: =Assumptions!E18 -> 0.09 | E17: =Assumptions!F18 -> 0.09 | F17: =Assumptions!G18 -> 0.09 | G17: =Assumptions!H18 -> 0.09
A18: LATAM revenue growth | B18: =Assumptions!C26 -> 0.08 | C18: =Assumptions!D26 -> 0.08 | D18: =Assumptions!E26 -> 0.08 | E18: =Assumptions!F26 -> 0.08 | F18: =Assumptions!G26 -> 0.08 | G18: =Assumptions!H26 -> 0.08
A19: APAC revenue growth | B19: =Assumptions!C34 -> 0.12 | C19: =Assumptions!D34 -> 0.12 | D19: =Assumptions!E34 -> 0.12 | E19: =Assumptions!F34 -> 0.12 | F19: =Assumptions!G34 -> 0.12 | G19: =Assumptions!H34 -> 0.12
A20: Content spend growth | B20: =Assumptions!C42 -> 0.1 | C20: =Assumptions!D42 -> 0.1 | D20: =Assumptions!E42 -> 0.1 | E20: =Assumptions!F42 -> 0.1 | F20: =Assumptions!G42 -> 0.1 | G20: =Assumptions!H42 -> 0.1

Sheet Proj Schedules
A1: Projection Schedules — supporting builds
B3: 2025A | C3: 2026E | D3: 2027E | E3: 2028E | F3: 2029E | G3: 2030E
A4: Revenue Build
A5: United States & Canada (UCAN) | B5: ='Revenue Modelling'!$D$4 -> 19957152 | C5: =B5*(1+'Proj Drivers'!C16) -> 20955010 | D5: =C5*(1+'Proj Drivers'!D16) -> 22002760 | E5: =D5*(1+'Proj Drivers'!E16) -> 23102898 | F5: =E5*(1+'Proj Drivers'!F16) -> 24258043 | G5: =F5*(1+'Proj Drivers'!G16) -> 25470945
A6: Europe, Middle East & Africa (EMEA) | B6: ='Revenue Modelling'!$D$6 -> 14514646 | C6: =B6*(1+'Proj Drivers'!C17) -> 15820964 | D6: =C6*(1+'Proj Drivers'!D17) -> 17244851 | E6: =D6*(1+'Proj Drivers'!E17) -> 18796887 | F6: =E6*(1+'Proj Drivers'!F17) -> 20488607 | G6: =F6*(1+'Proj Drivers'!G17) -> 22332582
A7: Latin America (LATAM) | B7: ='Revenue Modelling'!$D$8 -> 5357521 | C7: =B7*(1+'Proj Drivers'!C18) -> 5786122.7 | D7: =C7*(1+'Proj Drivers'!D18) -> 6249012.5 | E7: =D7*(1+'Proj Drivers'!E18) -> 6748933.5 | F7: =E7*(1+'Proj Drivers'!F18) -> 7288848.2 | G7: =F7*(1+'Proj Drivers'!G18) -> 7871956
A8: Asia-Pacific (APAC) | B8: ='Revenue Modelling'!$D$10 -> 5353717 | C8: =B8*(1+'Proj Drivers'!C19) -> 5996163 | D8: =C8*(1+'Proj Drivers'!D19) -> 6715702.6 | E8: =D8*(1+'Proj Drivers'!E19) -> 7521586.9 | F8: =E8*(1+'Proj Drivers'!F19) -> 8424177.3 | G8: =F8*(1+'Proj Drivers'!G19) -> 9435078.6
A9: Total revenue | B9: =SUM(B5:B8) -> 45183036 | C9: =SUM(C5:C8) -> 48558259 | D9: =SUM(D5:D8) -> 52212326 | E9: =SUM(E5:E8) -> 56170306 | F9: =SUM(F5:F8) -> 60459676 | G9: =SUM(G5:G8) -> 65110562
A11: Content Assets Rollforward
A12: Opening balance | B12: ='Balance Sheet Input'!$C$10 -> 32452462 | C12: =B16 -> 32778392 | D12: =C16 -> 35195475 | E12: =D16 -> 38284644 | F12: =E16 -> 41897919 | G12: =F16 -> 45980117
A13: Additions to content assets | B13: =-'CFS Input'!$D$6 -> 17096617 | C13: =B13*(1+'Proj Drivers'!C20) -> 18806279 | D13: =C13*(1+'Proj Drivers'!D20) -> 20686907 | E13: =D13*(1+'Proj Drivers'!E20) -> 22755597 | F13: =E13*(1+'Proj Drivers'!F20) -> 25031157 | G13: =F13*(1+'Proj Drivers'!G20) -> 27534273
A14: Amortization of content assets | B14: ='CFS Input'!$D$8 -> 16422166 | C14: =C12*'Model Control'!$C$12 -> 16389196 | D14: =D12*'Model Control'!$C$12 -> 17597737 | E14: =E12*'Model Control'!$C$12 -> 19142322 | F14: =F12*'Model Control'!$C$12 -> 20948960 | G14: =G12*'Model Control'!$C$12 -> 22990058
A16: Closing balance, content assets net | B16: ='Balance Sheet Input'!$D$10 -> 32778392 | C16: =C12+C13-C14 -> 35195475 | D16: =D12+D13-D14 -> 38284644 | E16: =E12+E13-E14 -> 41897919 | F16: =F12+F13-F14 -> 45980117 | G16: =G12+G13-G14 -> 50524331
A18: Property & Equipment Rollforward
A19: Opening balance | B19: ='Balance Sheet Input'!$C$11 -> 1593756 | C19: =B22 -> 2004350 | D19: =C22 -> 2313445 | E19: =D22 -> 2612693.1 | F19: =E22 -> 2908712.9 | G19: =F22 -> 3207150.5
A20: Capital expenditure | B20: =-'CFS Input'!$D$23 -> 688220 | C20: =C9*'Model Control'!$C$10 -> 728373.89 | D20: =D9*'Model Control'!$C$10 -> 783184.89 | E20: =E9*'Model Control'!$C$10 -> 842554.59 | F20: =F9*'Model Control'!$C$10 -> 906895.14 | G20: =G9*'Model Control'!$C$10 -> 976658.43
A21: Depreciation | B21: =Schedules!$D$6 -> 115710 | C21: =C19*'Model Control'!$C$11 -> 419278.89 | D21: =D19*'Model Control'!$C$11 -> 483936.76 | E21: =E19*'Model Control'!$C$11 -> 546534.82 | F21: =F19*'Model Control'!$C$11 -> 608457.56 | G21: =G19*'Model Control'!$C$11 -> 670886.07
A22: Closing balance, PP&E net | B22: ='Balance Sheet Input'!$D$11 -> 2004350 | C22: =C19+C20-C21 -> 2313445 | D22: =D19+D20-D21 -> 2612693.1 | E22: =E19+E20-E21 -> 2908712.9 | F22: =F19+F20-F21 -> 3207150.5 | G22: =G19+G20-G21 -> 3512922.8
A24: Debt & Interest Schedule
A25: Total debt, opening | B25: ='Balance Sheet Input'!$C$21+'Balance Sheet Input'!$C$24 -> 15582804 | C25: =B28 -> 14462836 | D25: =C28 -> 13462836 | E25: =D28 -> 11936836 | F25: =E28 -> 8436836 | G25: =F28 -> 4035836
A26: Scheduled repayments (face, by maturity) | B26: =-'CFS Input'!$D$31 -> 1833450 | C26: 1000000 | D26: 1526000 | E26: 3500000 | F26: 4401000 | G26: 2292000
A27: New borrowings | B27: 0 | C27: 0 | D27: 0 | E27: 0 | F27: 0 | G27: 0
A28: Total debt, closing | B28: ='Balance Sheet Input'!$D$21+'Balance Sheet Input'!$D$24 -> 14462836 | C28: =C25-C26+C27 -> 13462836 | D28: =D25-D26+D27 -> 11936836 | E28: =E25-E26+E27 -> 8436836 | F28: =F25-F26+F27 -> 4035836 | G28: =G25-G26+G27 -> 1743836
A29: Current portion (next-year maturity) | B29: ='Balance Sheet Input'!$D$21 -> 998865 | C29: 1526000 | D29: 3500000 | E29: 4401000 | F29: 2292000 | G29: 0
A30: Long-term portion | B30: ='Balance Sheet Input'!$D$24 -> 13463971 | C30: =C28-C29 -> 11936836 | D30: =D28-D29 -> 8436836 | E30: =E28-E29 -> 4035836 | F30: =F28-F29 -> 1743836 | G30: =G28-G29 -> 1743836
A31: Average debt | B31: =AVERAGE(B25,B28) -> 15022820 | C31: =AVERAGE(C25,C28) -> 13962836 | D31: =AVERAGE(D25,D28) -> 12699836 | E31: =AVERAGE(E25,E28) -> 10186836 | F31: =AVERAGE(F25,F28) -> 6236336 | G31: =AVERAGE(G25,G28) -> 2889836
A32: Interest expense | B32: =-'P&L Input'!$E$11 -> 776510 | C32: =C31*'Model Control'!$C$19 -> 664630.99 | D32: =D31*'Model Control'!$C$19 -> 604512.19 | E32: =E31*'Model Control'!$C$19 -> 484893.39 | F32: =F31*'Model Control'!$C$19 -> 296849.59 | G32: =G31*'Model Control'!$C$19 -> 137556.19
A34: Balance Sheet Driver Schedule
A35: Other current assets | B35: ='Balance Sheet Input'!$D$8 -> 3957832 | C35: =C9*'Proj Drivers'!C9 -> 4253509.3 | D35: =D9*'Proj Drivers'!D9 -> 4521378.6 | E35: =E9*'Proj Drivers'!E9 -> 4807953.5 | F35: =F9*'Proj Drivers'!F9 -> 5114646.7 | G35: =G9*'Proj Drivers'!G9 -> 5442982.5
A36: Accounts payable (DPO basis) | B36: ='Balance Sheet Input'!$D$18 -> 900612 | C36: ='Proj Drivers'!C10/365*(C9*'Proj Drivers'!C5) -> 967480.46 | D36: ='Proj Drivers'!D10/365*(D9*'Proj Drivers'!D5) -> 1041473.7 | E36: ='Proj Drivers'!E10/365*(E9*'Proj Drivers'!E5) -> 1121610.1 | F36: ='Proj Drivers'!F10/365*(F9*'Proj Drivers'!F5) -> 1208438.7 | G36: ='Proj Drivers'!G10/365*(G9*'Proj Drivers'!G5) -> 1293638.6
A37: Accrued expenses & other liabilities | B37: ='Balance Sheet Input'!$D$19 -> 3220869 | C37: =C9*'Proj Drivers'!C11 -> 3412917.3 | D37: =D9*'Proj Drivers'!D11 -> 3617531 | E37: =E9*'Proj Drivers'!E11 -> 3835589.3 | F37: =F9*'Proj Drivers'!F11 -> 4068029.3 | G37: =G9*'Proj Drivers'!G11 -> 4315853.6
A38: Deferred revenue | B38: ='Balance Sheet Input'!$D$20 -> 1775730 | C38: =C9*'Proj Drivers'!C12 -> 1908388.2 | D38: =D9*'Proj Drivers'!D12 -> 2051996.6 | E38: =E9*'Proj Drivers'!E12 -> 2151378.9 | F38: =F9*'Proj Drivers'!F12 -> 2315666 | G38: =G9*'Proj Drivers'!G12 -> 2428689.1
A39: Current content liabilities | B39: ='Balance Sheet Input'!$D$17 -> 4084854 | C39: =C9*'Model Control'!$C$13 -> 4370243.4 | D39: =D9*'Model Control'!$C$13 -> 4699109.3 | E39: =E9*'Model Control'!$C$13 -> 5055327.5 | F39: =F9*'Model Control'!$C$13 -> 5441370.8 | G39: =G9*'Model Control'!$C$13 -> 5859950.6
A40: Non-current content liabilities | B40: ='Balance Sheet Input'!$D$23 -> 1579476 | C40: =C9*'Model Control'!$C$14 -> 1699539.1 | D40: =D9*'Model Control'!$C$14 -> 1827431.4 | E40: =E9*'Model Control'!$C$14 -> 1965960.7 | F40: =F9*'Model Control'!$C$14 -> 2116088.7 | G40: =G9*'Model Control'!$C$14 -> 2278869.7
A41: Other non-current assets | B41: ='Balance Sheet Input'!$D$12 -> 7794060 | C41: =C9*'Model Control'!$C$15 -> 8376299.8 | D41: =D9*'Model Control'!$C$15 -> 9006626.3 | E41: =E9*'Model Control'!$C$15 -> 9689377.8 | F41: =F9*'Model Control'!$C$15 -> 10429294 | G41: =G9*'Model Control'!$C$15 -> 11231572
A42: Other non-current liabilities | B42: ='Balance Sheet Input'!$D$25 -> 2957128 | C42: =C9*'Model Control'!$C$16 -> 3180566 | D42: =D9*'Model Control'!$C$16 -> 3419907.4 | E42: =E9*'Model Control'!$C$16 -> 3679155 | F42: =F9*'Model Control'!$C$16 -> 3960108.8 | G42: =G9*'Model Control'!$C$16 -> 4264741.8
A43: Short-term investments | B43: ='Balance Sheet Input'!$D$7 -> 28678 | C43: ='Model Control'!$C$20 -> 28678 | D43: ='Model Control'!$C$20 -> 28678 | E43: ='Model Control'!$C$20 -> 28678 | F43: ='Model Control'!$C$20 -> 28678 | G43: ='Model Control'!$C$20 -> 28678
A45: Equity Rollforward
A46: Stock-based compensation | B46: ='CFS Input'!$D$10 -> 368449 | C46: =C9*'Model Control'!$C$17 -> 398177.73 | D46: =D9*'Model Control'!$C$17 -> 428141.07 | E46: =E9*'Model Control'!$C$17 -> 460596.51 | F46: =F9*'Model Control'!$C$17 -> 495769.34 | G46: =G9*'Model Control'!$C$17 -> 533906.61
A47: Stock issuance proceeds | B47: ='CFS Input'!$D$32 -> 666965 | C47: =C9*'Model Control'!$C$18 -> 718662.24 | D47: =D9*'Model Control'!$C$18 -> 772742.43 | E47: =E9*'Model Control'!$C$18 -> 831320.53 | F47: =F9*'Model Control'!$C$18 -> 894803.2 | G47: =G9*'Model Control'!$C$18 -> 963636.32
...

Sheet Projected PnL
A1: Netflix, Inc. — Projected Income Statement
A2: =CONCATENATE("Scenario: ",'Model Control'!$C$4) -> Scenario: Neutral Case
B3: 2025A | C3: 2026E | D3: 2027E | E3: 2028E | F3: 2029E | G3: 2030E
A4: Revenues | B4: ='P&L Input'!$E$3 -> 45183036 | C4: ='Proj Schedules'!C9 -> 48558259 | D4: ='Proj Schedules'!D9 -> 52212326 | E4: ='Proj Schedules'!E9 -> 56170306 | F4: ='Proj Schedules'!F9 -> 60459676 | G4: ='Proj Schedules'!G9 -> 65110562
A5: Cost of revenues | B5: ='P&L Input'!$E$4 -> 23275329 | C5: ='Proj Schedules'!C9*'Proj Drivers'!C5 -> 24868336 | D5: ='Proj Schedules'!D9*'Proj Drivers'!D5 -> 26583070 | E5: ='Proj Schedules'!E9*'Proj Drivers'!E5 -> 28429702 | F5: ='Proj Schedules'!F9*'Proj Drivers'!F5 -> 30419319 | G5: ='Proj Schedules'!G9*'Proj Drivers'!G5 -> 32564006
A6: Gross profit | B6: =B4-B5 -> 21907707 | C6: =C4-C5 -> 23689924 | D6: =D4-D5 -> 25629256 | E6: =E4-E5 -> 27740604 | F6: =F4-F5 -> 30040357 | G6: =G4-G5 -> 32546556
A7: Sales and marketing | B7: ='P&L Input'!$E$6 -> 3301306 | C7: ='Proj Schedules'!C9*'Proj Drivers'!C6 -> 3499351 | D7: ='Proj Schedules'!D9*'Proj Drivers'!D6 -> 3710469 | E7: ='Proj Schedules'!E9*'Proj Drivers'!E6 -> 3935572.5 | F7: ='Proj Schedules'!F9*'Proj Drivers'!F6 -> 4175647.5 | G7: ='Proj Schedules'!G9*'Proj Drivers'!G6 -> 4431750.4
A8: Technology and development | B8: ='P&L Input'!$E$7 -> 3391390 | C8: ='Proj Schedules'!C9*'Proj Drivers'!C7 -> 3644734.4 | D8: ='Proj Schedules'!D9*'Proj Drivers'!D7 -> 3866792.7 | E8: ='Proj Schedules'!E9*'Proj Drivers'!E7 -> 4103746.4 | F8: ='Proj Schedules'!F9*'Proj Drivers'!F7 -> 4356663.8 | G8: ='Proj Schedules'!G9*'Proj Drivers'!G7 -> 4626691.4
A9: General and administrative | B9: ='P&L Input'!$E$8 -> 1888408 | C9: ='Proj Schedules'!C9*'Proj Drivers'!C8 -> 1980934.2 | D9: ='Proj Schedules'!D9*'Proj Drivers'!D8 -> 2077789.5 | E9: ='Proj Schedules'!E9*'Proj Drivers'!E8 -> 2179127 | F9: ='Proj Schedules'!F9*'Proj Drivers'!F8 -> 2285073.4 | G9: ='Proj Schedules'!G9*'Proj Drivers'!G8 -> 2395743.1
A10: Operating income | B10: =B6-B7-B8-B9 -> 13326603 | C10: =C6-C7-C8-C9 -> 14564904 | D10: =D6-D7-D8-D9 -> 15974205 | E10: =E6-E7-E8-E9 -> 17522158 | F10: =F6-F7-F8-F9 -> 19222973 | G10: =G6-G7-G8-G9 -> 21092371
A11: Interest expense | B11: ='P&L Input'!$E$11 -> -776510 | C11: =-'Proj Schedules'!C32 -> -664630.99 | D11: =-'Proj Schedules'!D32 -> -604512.19 | E11: =-'Proj Schedules'!E32 -> -484893.39 | F11: =-'Proj Schedules'!F32 -> -296849.59 | G11: =-'Proj Schedules'!G32 -> -137556.19
A12: Interest and other income (expense) | B12: ='P&L Input'!$E$12 -> 172459 | C12: ='Proj Drivers'!C13 -> 50000 | D12: ='Proj Drivers'!D13 -> 75000 | E12: ='Proj Drivers'!E13 -> 100000 | F12: ='Proj Drivers'!F13 -> 100000 | G12: ='Proj Drivers'!G13 -> 125000
A13: Net income | B13: =B17+B18 -> 10981201 | C13: =C17+C18 -> 12040885 | D13: =D17+D18 -> 13330762 | E13: =E17+E18 -> 14791670 | F13: =F17+F18 -> 16421998 | G13: =G17+G18 -> 18194600
A15: Operating margin | B15: =B10/B4 -> 0.29494705 | C15: =C10/C4 -> 0.299947 | D15: =D10/D4 -> 0.305947 | E15: =E10/E4 -> 0.311947 | F15: =F10/F4 -> 0.317947 | G15: =G10/G4 -> 0.323947
A16: Net margin | B16: =B13/B4 -> 0.24303814 | C16: =C13/C4 -> 0.24796781 | D16: =D13/D4 -> 0.25531829 | E16: =E13/E4 -> 0.26333612 | F16: =F13/F4 -> 0.27161903 | G16: =G13/G4 -> 0.2794416
A17: Income before income taxes (EBT) | B17: =B10+B11+B12 -> 12722552 | C17: =C10+C11+C12 -> 13950273 | D17: =D10+D11+D12 -> 15444692 | E17: =E10+E11+E12 -> 17137265 | F17: =F10+F11+F12 -> 19026123 | G17: =G10+G11+G12 -> 21079815
A18: Provision for income taxes | B18: ='P&L Input'!$E$14 -> -1741351 | C18: =-C17*'Proj Drivers'!C14 -> -1909387.9 | D18: =-D17*'Proj Drivers'!D14 -> -2113930.5 | E18: =-E17*'Proj Drivers'!E14 -> -2345594.6 | F18: =-F17*'Proj Drivers'!F14 -> -2604124.5 | G18: =-G17*'Proj Drivers'!G14 -> -2885215.4

Sheet Projected BS
A1: Netflix, Inc. — Projected Balance Sheet
B3: 2025A | C3: 2026E | D3: 2027E | E3: 2028E | F3: 2029E | G3: 2030E
A4: Assets
A5: Cash and cash equivalents | B5: ='Balance Sheet Input'!$D$6 -> 9033681 | C5: ='Projected CFS'!C32 -> 9480609.9 | D5: ='Projected CFS'!D32 -> 10190790 | E5: ='Projected CFS'!E32 -> 9920161.5 | F5: ='Projected CFS'!F32 -> 10078002 | G5: ='Projected CFS'!G32 -> 13702418
A6: Short-term investments | B6: ='Balance Sheet Input'!$D$7 -> 28678 | C6: ='Proj Schedules'!C43 -> 28678 | D6: ='Proj Schedules'!D43 -> 28678 | E6: ='Proj Schedules'!E43 -> 28678 | F6: ='Proj Schedules'!F43 -> 28678 | G6: ='Proj Schedules'!G43 -> 28678
A7: Other current assets | B7: ='Balance Sheet Input'!$D$8 -> 3957832 | C7: ='Proj Schedules'!C35 -> 4253509.3 | D7: ='Proj Schedules'!D35 -> 4521378.6 | E7: ='Proj Schedules'!E35 -> 4807953.5 | F7: ='Proj Schedules'!F35 -> 5114646.7 | G7: ='Proj Schedules'!G35 -> 5442982.5
A8: Total current assets | B8: =SUM(B5:B7) -> 13020191 | C8: =SUM(C5:C7) -> 13762797 | D8: =SUM(D5:D7) -> 14740847 | E8: =SUM(E5:E7) -> 14756793 | F8: =SUM(F5:F7) -> 15221326 | G8: =SUM(G5:G7) -> 19174078
A9: Content assets, net | B9: ='Balance Sheet Input'!$D$10 -> 32778392 | C9: ='Proj Schedules'!C16 -> 35195475 | D9: ='Proj Schedules'!D16 -> 38284644 | E9: ='Proj Schedules'!E16 -> 41897919 | F9: ='Proj Schedules'!F16 -> 45980117 | G9: ='Proj Schedules'!G16 -> 50524331
A10: Property and equipment, net | B10: ='Balance Sheet Input'!$D$11 -> 2004350 | C10: ='Proj Schedules'!C22 -> 2313445 | D10: ='Proj Schedules'!D22 -> 2612693.1 | E10: ='Proj Schedules'!E22 -> 2908712.9 | F10: ='Proj Schedules'!F22 -> 3207150.5 | G10: ='Proj Schedules'!G22 -> 3512922.8
A11: Other non-current assets | B11: ='Balance Sheet Input'!$D$12 -> 7794060 | C11: ='Proj Schedules'!C41 -> 8376299.8 | D11: ='Proj Schedules'!D41 -> 9006626.3 | E11: ='Proj Schedules'!E41 -> 9689377.8 | F11: ='Proj Schedules'!F41 -> 10429294 | G11: ='Proj Schedules'!G41 -> 11231572
A12: Total assets | B12: =B8+B9+B10+B11 -> 55596993 | C12: =C8+C9+C10+C11 -> 59648017 | D12: =D8+D9+D10+D11 -> 64644810 | E12: =E8+E9+E10+E11 -> 69252803 | F12: =F8+F9+F10+F11 -> 74837888 | G12: =G8+G9+G10+G11 -> 84442904
A14: Liabilities and Stockholders' Equity
A15: Current content liabilities | B15: ='Balance Sheet Input'!$D$17 -> 4084854 | C15: ='Proj Schedules'!C39 -> 4370243.4 | D15: ='Proj Schedules'!D39 -> 4699109.3 | E15: ='Proj Schedules'!E39 -> 5055327.5 | F15: ='Proj Schedules'!F39 -> 5441370.8 | G15: ='Proj Schedules'!G39 -> 5859950.6
A16: Accounts payable | B16: ='Balance Sheet Input'!$D$18 -> 900612 | C16: ='Proj Schedules'!C36 -> 967480.46 | D16: ='Proj Schedules'!D36 -> 1041473.7 | E16: ='Proj Schedules'!E36 -> 1121610.1 | F16: ='Proj Schedules'!F36 -> 1208438.7 | G16: ='Proj Schedules'!G36 -> 1293638.6
A17: Accrued expenses and other liabilities | B17: ='Balance Sheet Input'!$D$19 -> 3220869 | C17: ='Proj Schedules'!C37 -> 3412917.3 | D17: ='Proj Schedules'!D37 -> 3617531 | E17: ='Proj Schedules'!E37 -> 3835589.3 | F17: ='Proj Schedules'!F37 -> 4068029.3 | G17: ='Proj Schedules'!G37 -> 4315853.6
A18: Deferred revenue | B18: ='Balance Sheet Input'!$D$20 -> 1775730 | C18: ='Proj Schedules'!C38 -> 1908388.2 | D18: ='Proj Schedules'!D38 -> 2051996.6 | E18: ='Proj Schedules'!E38 -> 2151378.9 | F18: ='Proj Schedules'!F38 -> 2315666 | G18: ='Proj Schedules'!G38 -> 2428689.1
A19: Short-term debt | B19: ='Balance Sheet Input'!$D$21 -> 998865 | C19: ='Proj Schedules'!C29 -> 1526000 | D19: ='Proj Schedules'!D29 -> 3500000 | E19: ='Proj Schedules'!E29 -> 4401000 | F19: ='Proj Schedules'!F29 -> 2292000 | G19: ='Proj Schedules'!G29 -> 0
A20: Total current liabilities | B20: =SUM(B15:B19) -> 10980930 | C20: =SUM(C15:C19) -> 12185029 | D20: =SUM(D15:D19) -> 14910111 | E20: =SUM(E15:E19) -> 16564906 | F20: =SUM(F15:F19) -> 15325505 | G20: =SUM(G15:G19) -> 13898132
A21: Non-current content liabilities | B21: ='Balance Sheet Input'!$D$23 -> 1579476 | C21: ='Proj Schedules'!C40 -> 1699539.1 | D21: ='Proj Schedules'!D40 -> 1827431.4 | E21: ='Proj Schedules'!E40 -> 1965960.7 | F21: ='Proj Schedules'!F40 -> 2116088.7 | G21: ='Proj Schedules'!G40 -> 2278869.7
A22: Long-term debt | B22: ='Balance Sheet Input'!$D$24 -> 13463971 | C22: ='Proj Schedules'!C30 -> 11936836 | D22: ='Proj Schedules'!D30 -> 8436836 | E22: ='Proj Schedules'!E30 -> 4035836 | F22: ='Proj Schedules'!F30 -> 1743836 | G22: ='Proj Schedules'!G30 -> 1743836
A23: Other non-current liabilities | B23: ='Balance Sheet Input'!$D$25 -> 2957128 | C23: ='Proj Schedules'!C42 -> 3180566 | D23: ='Proj Schedules'!D42 -> 3419907.4 | E23: ='Proj Schedules'!E42 -> 3679155 | F23: ='Proj Schedules'!F42 -> 3960108.8 | G23: ='Proj Schedules'!G42 -> 4264741.8
